2017-05-26 15:51:52,658 - INFO - [Elapsed time: 0.00] Error: Galaxy isn't running/connection error.
2017-05-26 15:51:52,658 - INFO - [Elapsed time: 0.01] Waiting 30 seconds...
2017-05-26 15:52:06,208 - INFO - [Elapsed time: 13.56] [Error Dump]
Traceback (most recent call last):
  File "/home/devon/PycharmProjects/auto-SNVPhyl/main.py", line 501, in wait_for_problem
    self.gi.histories.get_histories()
  File "/usr/local/lib/python3.5/dist-packages/bioblend/galaxy/histories/__init__.py", line 58, in get_histories
    histories = Client._get(self, deleted=deleted)
  File "/usr/local/lib/python3.5/dist-packages/bioblend/galaxy/client.py", line 133, in _get
    status_code=r.status_code)
bioblend.ConnectionError: HTTPConnectionPool(host='192.168.1.3', port=48888): Max retries exceeded with url: /api/histories?key=6589a82d08d7e9a5ff3f64dcc8fc3592 (Caused by NewConnectionError('<requests.packages.urllib3.connection.HTTPConnection object at 0x7f31d8c9e1d0>: Failed to establish a new connection: [Errno 111] Connection refused',)), 0 attempts left: 

During handling of the above exception, another exception occurred:

Traceback (most recent call last):
  File "/home/devon/PycharmProjects/auto-SNVPhyl/main.py", line 41, in run
    self.wait_for_problem()
  File "/home/devon/PycharmProjects/auto-SNVPhyl/main.py", line 512, in wait_for_problem
    time.sleep(30)
KeyboardInterrupt

